<?xml version="1.0" ?>
<robot name="mechaship"
  xmlns:xacro="http://ros.org/wiki/xacro">

  <!-- Init colour -->
  <material name="black">
      <color rgba="0.0 0.0 0.0 1.0"/>
  </material>

  <material name="dark">
    <color rgba="0.3 0.3 0.3 1.0"/>
  </material>

  <material name="grey">
    <color rgba="0.5 0.5 0.5 1.0"/>
  </material>

  <material name="green">
    <color rgba="0.8 1 0.8 1.0"/>
  </material>

  <material name="orange">
    <color rgba="1.0 0.5 0.4 1.0"/>
  </material>

  <link name="base_footprint"/>

  <joint name="base_joint" type="fixed">
    <parent link="base_footprint"/>
    <child link="base_link"/>
    <origin xyz="0 0 0" rpy="0 0 0"/>
  </joint>

  <link name="base_link">
    <visual>
      <origin xyz="0 0 0" rpy="0 0 0"/>
      <geometry>
        <mesh filename="file://$(find mechaship_description)/meshes/body.stl" scale="0.001 0.001 0.001"/>
      </geometry>
      <material name="dark"/>
    </visual>

    <collision>
      <origin xyz="0 0 0" rpy="0 0 0"/>
      <geometry>
        <mesh filename="file://$(find mechaship_description)/meshes/body.stl" scale="0.001 0.001 0.001"/>
      </geometry>
    </collision>

    <inertial>
      <origin xyz="0 0 0" rpy="0 0 0"/>
      <mass value="1.0"/>
      <inertia ixx="1.0" ixy="0.0" ixz="0.0" iyy="1.0" iyz="0.0" izz="1.0"/>
    </inertial>
  </link>

  <joint name="imu_joint" type="fixed">
    <parent link="base_link"/>
    <child link="imu_link"/>
  </joint>

  <link name="imu_link"/>

  <joint name="scan_joint" type="fixed">
    <parent link="base_link"/>
    <child link="base_scan"/>
    <origin xyz="-0.072 0 0.207947" rpy="0 0 0"/>
    <inertial>
      <mass value="0.114" />
      <origin xyz="0 0 0" />
      <inertia ixx="0.001" ixy="0.0" ixz="0.0" iyy="0.001" iyz="0.0" izz="0.001" />
    </inertial>
  </joint>

  <link name="base_scan">
    <visual>
      <origin xyz="0 0 -0.022" rpy="0 0 0"/>
      <geometry>
        <mesh filename="file://$(find mechaship_description)/meshes/ydlidar_x4.stl" scale="0.001 0.001 0.001"/>
      </geometry>
      <material name="green"/>
    </visual>

    <collision>
      <origin xyz="0 0 -0.022" rpy="0 0 0"/>
      <geometry>
        <mesh filename="file://$(find mechaship_description)/meshes/ydlidar_x4.stl" scale="0.001 0.001 0.001"/>
      </geometry>
    </collision>

    <inertial>
      <mass value="0.114" />
      <origin xyz="0 0 0" />
      <inertia ixx="0.001" ixy="0.0" ixz="0.0" iyy="0.001" iyz="0.0" izz="0.001" />
    </inertial>
  </link>

  <gazebo reference="base_scan">
    <sensor name="ydlidar" type="ray">
      <always_on>true</always_on>
      <visualize>true</visualize>
      <pose>0 0 0.081 0 0 0</pose>
      <update_rate>5</update_rate>
      <ray>
        <scan>
          <horizontal>
            <samples>360</samples>
            <resolution>1.000000</resolution>
            <min_angle>0.000000</min_angle>
            <max_angle>6.280000</max_angle>
          </horizontal>
        </scan>
        <range>
          <min>0.120000</min>
          <max>3.0</max>
          <resolution>0.015000</resolution>
        </range>
        <noise>
          <type>gaussian</type>
          <mean>0.0</mean>
          <stddev>0.01</stddev>
        </noise>
      </ray>
      <plugin name="mechaship_laserscan" filename="libgazebo_ros_ray_sensor.so">
        <ros>
          <remapping>~/out:=scan</remapping>
        </ros>
        <output_type>sensor_msgs/LaserScan</output_type>
        <frame_name>base_scan</frame_name>
      </plugin>
    </sensor>
  </gazebo>

  <joint name="thruster_joint" type="revolute">
    <origin xyz="-0.247662 0 0.109197" rpy="0 0 0"/>
    <parent link="base_link"/>
    <child link="thruster_link"/>
    <axis xyz="0.0 0.0 1.0"/>
    <limit lower="-1.5708" upper="1.5708" effort="1.0" velocity="3.1415"/>
  </joint>

  <link name="thruster_link">
    <visual>
      <origin xyz="0 0 -0.063" rpy="0 0 0"/>
      <geometry>
        <mesh filename="file://$(find mechaship_description)/meshes/thruster.stl" scale="0.001 0.001 0.001"/>
      </geometry>
      <material name="orange"/>
    </visual>

    <collision>
      <origin xyz="0 0 -0.063" rpy="0 0 0"/>
      <geometry>
        <mesh filename="file://$(find mechaship_description)/meshes/thruster.stl" scale="0.001 0.001 0.001"/>
      </geometry>
    </collision>

    <inertial>
      <mass value="0.114"/>
      <origin xyz="0 0 0"/>
      <inertia ixx="0.001" ixy="0.0" ixz="0.0" iyy="0.001" iyz="0.0" izz="0.001" />
    </inertial>
  </link>

  <transmission name="thruster_trans" type="SimpleTransmission">
    <type>transmission_interface/SimpleTransmission</type>
    <actuator name="thruster_key_motor">
    <hardwareInterface>hardware_interface/PositionJointInterface</hardwareInterface>
    <mechanicalReduction>1</mechanicalReduction>
    </actuator>
    <joint name="thruster_joint">
    <hardwareInterface>hardware_interface/PositionJointInterface</hardwareInterface>
    </joint>
  </transmission>

  <gazebo>
    <plugin name="mechaship_joint_state" filename="libgazebo_ros_joint_state_publisher.so">
      <ros>
        <remapping>~/out:=joint_states</remapping>
      </ros>
      <update_rate>30</update_rate>
      <joint_name>thruster_joint</joint_name>
    </plugin>
  </gazebo>

  <joint name="camera_joint" type="fixed">
    <parent link="base_link"/>
    <child link="camera_link"/>
    <origin xyz="0.228391 0 0.148972" rpy="-1.5708 0.0680678 0"/>
  </joint>

  <link name="camera_link">
    <visual>
      <origin xyz="-0.0067 0.00255 0" rpy="0 0 0"/>
      <geometry>
        <mesh filename="file://$(find mechaship_description)/meshes/rpi_camera_v2.stl" scale="0.001 0.001 0.001"/>
      </geometry>
      <material name="green"/>
    </visual>

    <collision>
      <origin xyz="-0.0067 0.00255 0" rpy="0 0 0"/>
      <geometry>
        <mesh filename="file://$(find mechaship_description)/meshes/rpi_camera_v2.stl" scale="0.001 0.001 0.001"/>
      </geometry>
    </collision>

    <inertial>
      <mass value="0.114" />
      <origin xyz="0 0 0" />
      <inertia ixx="0.001" ixy="0.0" ixz="0.0" iyy="0.001" iyz="0.0" izz="0.001" />
    </inertial>
  </link>

</robot>
